Workbook

Sheet Employee Data
A1: No. | B1: Code | C1: Status | D1: Employee Name in English | E1: Employee Name in Arabic | F1: Job title in Arabic | G1: Job title in English | H1: SI Job Code | I1: Social Insurance Title | J1: Department | K1: Sector | L1: Site | M1: Weekly Days off | N1: Meal Allowance | O1: Overtime | P1: Bus Route | Q1: Hiring Date | R1: Work Period | S1: Mobile No. | T1: Sec. Mobile No. | U1: SI No. | V1: SI Status | W1: SI Basic Wage | X1: SI Gross Wage | Y1: Med. Insurance | Z1: ID No. | AA1: Date Of Birth | AB1: Age | AC1: ID Issuing Date | AD1: ID Exp. Date | AE1: Gender | AF1: Military Service | AG1: Marital Status | AH1: Religion | AI1: Qualification Degree | AJ1: Original Graduation Certificate | AK1: Original Military Certificate | AL1: Original Birth Certificate | AM1: Finger Print Record | AN1: ID Copy | AO1: 6 Personal Photos | AP1: Medical Form No. 111 | AQ1: SI Record | AR1: Copy SI Form 1 | AS1: Copy SI Form 6 | AT1: Contract | AU1: File Status | AV1: Comments | AW1: Notice Date | AX1: Resignation Date | AY1: Resignation Reason
A2: =ROW()-1 -> 1 | B2: 240001 | C2: On-Board | D2: Ahmed Moustafa Mohamed | E2: احمد مصطفى محمد حسن | F2: العضو المنتدب | G2: CEO | I2: =IFERROR(VLOOKUP(H2,'SI Codes'!$A:$B,2,FALSE()),"") | J2: CEO | K2: =IFERROR(VLOOKUP(J2,Lists!$I$1:$J$21,2,FALSE()),"") -> GM | L2: Factory 1 | M2: Saturdays and Fridays | N2: No | O2: No | Q2: 45505 | R2: =IF(Q2="","",IF(C2="Resigned",IF(AX2="","",DATEDIF(Q2,AX2,"y")&"y "&DATEDIF(Q2,AX2,"ym")&"m"),DATEDIF(Q2,TODAY(),"y")&"y "&DATEDIF(Q2,TODAY(),"ym")&"m")) -> 1y 5m | S2: 1271301076 | T2: 1206037776 | U2: 13707503 | V2: Yes | Z2: 28803080200111 | AA2: =IFERROR(DATE(IF(LEFT(Z2,1)="2",1900,2000)+VALUE(MID(Z2,2,2)),VALUE(MID(Z2,4,2)),VALUE(MID(Z2,6,2))),"") -> 32210 | AB2: =IF(AA2="","",DATEDIF(AA2,TODAY(),"y")&"y "&DATEDIF(AA2,TODAY(),"ym")&"m") -> 37y 9m | AE2: Male | AF2: Served | AG2: Married | AH2: Muslim | AI2: بكالوريوس هندسة | AU2: =IF(COUNTIF(AJ2:AT2,"Yes")=COLUMNS(AJ2:AT2),"Yes","No") -> No
A3: =ROW()-1 -> 2 | B3: 240003 | C3: On-Board | D3: Islam Said Elsayed | E3: اسلام سعيد السيد اسماعيل | F3: مدير ادارة الابحاث والتطوير | G3: R&D Manager | I3: =IFERROR(VLOOKUP(H3,'SI Codes'!$A:$B,2,FALSE()),"") | J3: Tendering | K3: =IFERROR(VLOOKUP(J3,Lists!$I$1:$J$21,2,FALSE()),"") -> R&D | L3: Factory 1 | M3: Saturdays and Fridays | N3: No | O3: No | Q3: 45505 | R3: =IF(Q3="","",IF(C3="Resigned",IF(AX3="","",DATEDIF(Q3,AX3,"y")&"y "&DATEDIF(Q3,AX3,"ym")&"m"),DATEDIF(Q3,TODAY(),"y")&"y "&DATEDIF(Q3,TODAY(),"ym")&"m")) -> 1y 5m | S3: 1061684411 | T3: 1272832690 | U3: 78220556 | V3: Yes | Z3: 29306061300156 | AA3: =IFERROR(DATE(IF(LEFT(Z3,1)="2",1900,2000)+VALUE(MID(Z3,2,2)),VALUE(MID(Z3,4,2)),VALUE(MID(Z3,6,2))),"") -> 34126 | AB3: =IF(AA3="","",DATEDIF(AA3,TODAY(),"y")&"y "&DATEDIF(AA3,TODAY(),"ym")&"m") -> 32y 6m | AE3: Male | AG3: Single | AH3: Muslim | AI3: بكالوريوس هندسة | AU3: =IF(COUNTIF(AJ3:AT3,"Yes")=COLUMNS(AJ3:AT3),"Yes","No") -> No
A4: =ROW()-1 -> 3 | B4: 240004 | C4: On-Board | D4: Ahmed Adel Ahmed | E4: احمد عادل عبدالعزيز طه | F4: اخصائي موارد بشرية | G4: HR Specialist | I4: =IFERROR(VLOOKUP(H4,'SI Codes'!$A:$B,2,FALSE()),"") | J4: HR | K4: =IFERROR(VLOOKUP(J4,Lists!$I$1:$J$21,2,FALSE()),"") -> HR and Admin | L4: Factory 1 | M4: Saturdays and Fridays | N4: No | O4: No | Q4: 45505 | R4: =IF(Q4="","",IF(C4="Resigned",IF(AX4="","",DATEDIF(Q4,AX4,"y")&"y "&DATEDIF(Q4,AX4,"ym")&"m"),DATEDIF(Q4,TODAY(),"y")&"y "&DATEDIF(Q4,TODAY(),"ym")&"m")) -> 1y 5m | S4: 1226067738 | T4: 1129525516 | U4: 67950739 | V4: Yes | Z4: 29803010110755 | AA4: =IFERROR(DATE(IF(LEFT(Z4,1)="2",1900,2000)+VALUE(MID(Z4,2,2)),VALUE(MID(Z4,4,2)),VALUE(MID(Z4,6,2))),"") -> 35855 | AB4: =IF(AA4="","",DATEDIF(AA4,TODAY(),"y")&"y "&DATEDIF(AA4,TODAY(),"ym")&"m") -> 27y 10m | AE4: Male | AG4: Married | AH4: Muslim | AI4: ليسانس اداب | AU4: =IF(COUNTIF(AJ4:AT4,"Yes")=COLUMNS(AJ4:AT4),"Yes","No") -> No
A5: =ROW()-1 -> 4 | B5: 240005 | C5: On-Board | D5: Doaa Ramadan Mohamed | E5: دعاء رمضان محمد احمد | F5: مدير المشتريات | G5: Supply Chain Manager | I5: =IFERROR(VLOOKUP(H5,'SI Codes'!$A:$B,2,FALSE()),"") | J5: Foreign Purchasing | K5: =IFERROR(VLOOKUP(J5,Lists!$I$1:$J$21,2,FALSE()),"") -> Supply Chain | L5: Factory 1 | M5: Saturdays and Fridays | N5: No | O5: No | Q5: 45505 | R5: =IF(Q5="","",IF(C5="Resigned",IF(AX5="","",DATEDIF(Q5,AX5,"y")&"y "&DATEDIF(Q5,AX5,"ym")&"m"),DATEDIF(Q5,TODAY(),"y")&"y "&DATEDIF(Q5,TODAY(),"ym")&"m")) -> 1y 5m | S5: 1272845302 | T5: 1011251189 | AA5: =IFERROR(DATE(IF(LEFT(Z5,1)="2",1900,2000)+VALUE(MID(Z5,2,2)),VALUE(MID(Z5,4,2)),VALUE(MID(Z5,6,2))),"") | AB5: =IF(AA5="","",DATEDIF(AA5,TODAY(),"y")&"y "&DATEDIF(AA5,TODAY(),"ym")&"m") | AE5: Female | AG5: Married | AH5: Muslim | AU5: =IF(COUNTIF(AJ5:AT5,"Yes")=COLUMNS(AJ5:AT5),"Yes","No") -> No
A6: =ROW()-1 -> 5 | B6: 240006 | C6: On-Board | D6: Naama Ebrahim Ahmed | E6: نعمة ابراهيم احمد | F6: عاملة بوفيه | G6: Office Girl | I6: =IFERROR(VLOOKUP(H6,'SI Codes'!$A:$B,2,FALSE()),"") | J6: Buffet | K6: =IFERROR(VLOOKUP(J6,Lists!$I$1:$J$21,2,FALSE()),"") -> HR and Admin | L6: Factory 1 | M6: Saturdays and Fridays | N6: Yes | O6: Yes | Q6: 45505 | R6: =IF(Q6="","",IF(C6="Resigned",IF(AX6="","",DATEDIF(Q6,AX6,"y")&"y "&DATEDIF(Q6,AX6,"ym")&"m"),DATEDIF(Q6,TODAY(),"y")&"y "&DATEDIF(Q6,TODAY(),"ym")&"m")) -> 1y 5m | S6: 1122572244 | U6: 85861868 | V6: Yes | Z6: 28509142106364 | AA6: =IFERROR(DATE(IF(LEFT(Z6,1)="2",1900,2000)+VALUE(MID(Z6,2,2)),VALUE(MID(Z6,4,2)),VALUE(MID(Z6,6,2))),"") -> 31304 | AB6: =IF(AA6="","",DATEDIF(AA6,TODAY(),"y")&"y "&DATEDIF(AA6,TODAY(),"ym")&"m") -> 40y 3m | AE6: Female | AG6: Married | AH6: Muslim | AI6: دبلوم تجارة | AU6: =IF(COUNTIF(AJ6:AT6,"Yes")=COLUMNS(AJ6:AT6),"Yes","No") -> No
A7: =ROW()-1 -> 6 | B7: 240009 | C7: On-Board | D7: Karim Magdy Attia | E7: كريم مجدي عطية | F7: مشرف أمن | G7: Security Supervisor | I7: =IFERROR(VLOOKUP(H7,'SI Codes'!$A:$B,2,FALSE()),"") | J7: Security | K7: =IFERROR(VLOOKUP(J7,Lists!$I$1:$J$21,2,FALSE()),"") -> HR and Admin | L7: Factory 1 | M7: Fridays Only | N7: Yes | O7: Yes | Q7: 45597 | R7: =IF(Q7="","",IF(C7="Resigned",IF(AX7="","",DATEDIF(Q7,AX7,"y")&"y "&DATEDIF(Q7,AX7,"ym")&"m"),DATEDIF(Q7,TODAY(),"y")&"y "&DATEDIF(Q7,TODAY(),"ym")&"m")) -> 1y 2m | S7: 1272836708 | T7: 1144192363 | U7: 71551980 | V7: Yes | Z7: 29503032100377 | AA7: =IFERROR(DATE(IF(LEFT(Z7,1)="2",1900,2000)+VALUE(MID(Z7,2,2)),VALUE(MID(Z7,4,2)),VALUE(MID(Z7,6,2))),"") -> 34761 | AB7: =IF(AA7="","",DATEDIF(AA7,TODAY(),"y")&"y "&DATEDIF(AA7,TODAY(),"ym")&"m") -> 30y 9m | AE7: Male | AG7: Single | AH7: Muslim | AI7: بكالوريوس خدمة اجتماعية | AU7: =IF(COUNTIF(AJ7:AT7,"Yes")=COLUMNS(AJ7:AT7),"Yes","No") -> No
A8: =ROW()-1 -> 7 | B8: 240010 | C8: On-Board | D8: Antabah Lesha Fahmy | E8: انتباه ليشع فهمي | F8: عاملة خدمات | G8: Clean Service | I8: =IFERROR(VLOOKUP(H8,'SI Codes'!$A:$B,2,FALSE()),"") | J8: Service | K8: =IFERROR(VLOOKUP(J8,Lists!$I$1:$J$21,2,FALSE()),"") -> HR and Admin | L8: Factory 1 | M8: Fridays Only | N8: Yes | O8: Yes | Q8: 45627 | R8: =IF(Q8="","",IF(C8="Resigned",IF(AX8="","",DATEDIF(Q8,AX8,"y")&"y "&DATEDIF(Q8,AX8,"ym")&"m"),DATEDIF(Q8,TODAY(),"y")&"y "&DATEDIF(Q8,TODAY(),"ym")&"m")) -> 1y 1m | S8: 1286744105 | U8: 76595162 | V8: Yes | Z8: 28808222502627 | AA8: =IFERROR(DATE(IF(LEFT(Z8,1)="2",1900,2000)+VALUE(MID(Z8,2,2)),VALUE(MID(Z8,4,2)),VALUE(MID(Z8,6,2))),"") -> 32377 | AB8: =IF(AA8="","",DATEDIF(AA8,TODAY(),"y")&"y "&DATEDIF(AA8,TODAY(),"ym")&"m") -> 37y 4m | AE8: Female | AG8: Married | AH8: Christian | AI8: بدون مؤهل | AU8: =IF(COUNTIF(AJ8:AT8,"Yes")=COLUMNS(AJ8:AT8),"Yes","No") -> No
A9: =ROW()-1 -> 8 | B9: 240011 | C9: On-Board | D9: Nesma Abo Elkhier | E9: نسمة ابو الخير علواني | F9: مدير الجودة | G9: Quality Manager | I9: =IFERROR(VLOOKUP(H9,'SI Codes'!$A:$B,2,FALSE()),"") | J9: Quality | K9: =IFERROR(VLOOKUP(J9,Lists!$I$1:$J$21,2,FALSE()),"") -> Operations | L9: Factory 1 | M9: Saturdays and Fridays | N9: No | O9: No | Q9: 45641 | R9: =IF(Q9="","",IF(C9="Resigned",IF(AX9="","",DATEDIF(Q9,AX9,"y")&"y "&DATEDIF(Q9,AX9,"ym")&"m"),DATEDIF(Q9,TODAY(),"y")&"y "&DATEDIF(Q9,TODAY(),"ym")&"m")) -> 1y 0m | S9: 1272832504 | T9: 1159888743 | U9: 55752679 | V9: Yes | Z9: 29011172201246 | AA9: =IFERROR(DATE(IF(LEFT(Z9,1)="2",1900,2000)+VALUE(MID(Z9,2,2)),VALUE(MID(Z9,4,2)),VALUE(MID(Z9,6,2))),"") -> 33194 | AB9: =IF(AA9="","",DATEDIF(AA9,TODAY(),"y")&"y "&DATEDIF(AA9,TODAY(),"ym")&"m") -> 35y 1m | AE9: Female | AG9: Married | AH9: Muslim | AI9: بكالوريوس هندسة | AU9: =IF(COUNTIF(AJ9:AT9,"Yes")=COLUMNS(AJ9:AT9),"Yes","No") -> No
A10: =ROW()-1 -> 9 | B10: 250012 | C10: On-Board | D10: Duha Elsayed Ali | E10: ضحى السيد علي السيد | F10: محاسب عام | G10: Financial Specialist | I10: =IFERROR(VLOOKUP(H10,'SI Codes'!$A:$B,2,FALSE()),"") | J10: Finance | K10: =IFERROR(VLOOKUP(J10,Lists!$I$1:$J$21,2,FALSE()),"") -> Finance | L10: Factory 1 | M10: Saturdays and Fridays | N10: No | O10: No | Q10: 45658 | R10: =IF(Q10="","",IF(C10="Resigned",IF(AX10="","",DATEDIF(Q10,AX10,"y")&"y "&DATEDIF(Q10,AX10,"ym")&"m"),DATEDIF(Q10,TODAY(),"y")&"y "&DATEDIF(Q10,TODAY(),"ym")&"m")) -> 1y 0m | S10: 1272831470 | U10: 85960001 | V10: Yes | Z10: 29804142602467 | AA10: =IFERROR(DATE(IF(LEFT(Z10,1)="2",1900,2000)+VALUE(MID(Z10,2,2)),VALUE(MID(Z10,4,2)),VALUE(MID(Z10,6,2))),"") -> 35899 | AB10: =IF(AA10="","",DATEDIF(AA10,TODAY(),"y")&"y "&DATEDIF(AA10,TODAY(),"ym")&"m") -> 27y 8m | AE10: Female | AG10: Single | AH10: Muslim | AI10: بكالوريوس تجارة | AU10: =IF(COUNTIF(AJ10:AT10,"Yes")=COLUMNS(AJ10:AT10),"Yes","No") -> No
A11: =ROW()-1 -> 10 | B11: 250013 | C11: On-Board | D11: Mahmoud Sayed Ebrahim | E11: محمود سيد ابراهيم | F11: فني صيانة | G11: Maintanance Technicion | I11: =IFERROR(VLOOKUP(H11,'SI Codes'!$A:$B,2,FALSE()),"") | J11: Maintenance | K11: =IFERROR(VLOOKUP(J11,Lists!$I$1:$J$21,2,FALSE()),"") -> Operations | L11: Factory 1 | M11: Fridays Only | N11: Yes | O11: Yes | Q11: 45689 | R11: =IF(Q11="","",IF(C11="Resigned",IF(AX11="","",DATEDIF(Q11,AX11,"y")&"y "&DATEDIF(Q11,AX11,"ym")&"m"),DATEDIF(Q11,TODAY(),"y")&"y "&DATEDIF(Q11,TODAY(),"ym")&"m")) -> 0y 11m | S11: 1281370295 | U11: 81744149 | V11: Yes | Z11: 29911172200798 | AA11: =IFERROR(DATE(IF(LEFT(Z11,1)="2",1900,2000)+VALUE(MID(Z11,2,2)),VALUE(MID(Z11,4,2)),VALUE(MID(Z11,6,2))),"") -> 36481 | AB11: =IF(AA11="","",DATEDIF(AA11,TODAY(),"y")&"y "&DATEDIF(AA11,TODAY(),"ym")&"m") -> 26y 1m | AE11: Male | AG11: Married | AH11: Muslim | AI11: دبلوم صناعة | AU11: =IF(COUNTIF(AJ11:AT11,"Yes")=COLUMNS(AJ11:AT11),"Yes","No") -> No
A12: =ROW()-1 -> 11 | B12: 250014 | C12: On-Board | D12: Abdalla Nabil | E12: عبدالله نبيل فضل | F12: فني انتاج | G12: Production Operator | I12: =IFERROR(VLOOKUP(H12,'SI Codes'!$A:$B,2,FALSE()),"") | J12: Production | K12: =IFERROR(VLOOKUP(J12,Lists!$I$1:$J$21,2,FALSE()),"") -> Operations | L12: Factory 1 | M12: Fridays Only | N12: Yes | O12: Yes | Q12: 45762 | R12: =IF(Q12="","",IF(C12="Resigned",IF(AX12="","",DATEDIF(Q12,AX12,"y")&"y "&DATEDIF(Q12,AX12,"ym")&"m"),DATEDIF(Q12,TODAY(),"y")&"y "&DATEDIF(Q12,TODAY(),"ym")&"m")) -> 0y 8m | S12: 1117933811 | U12: 86945841 | V12: Yes | Z12: 30607072103471 | AA12: =IFERROR(DATE(IF(LEFT(Z12,1)="2",1900,2000)+VALUE(MID(Z12,2,2)),VALUE(MID(Z12,4,2)),VALUE(MID(Z12,6,2))),"") -> 38905 | AB12: =IF(AA12="","",DATEDIF(AA12,TODAY(),"y")&"y "&DATEDIF(AA12,TODAY(),"ym")&"m") -> 19y 5m | AE12: Male | AG12: Single | AH12: Muslim | AI12: دبلوم فني | AU12: =IF(COUNTIF(AJ12:AT12,"Yes")=COLUMNS(AJ12:AT12),"Yes","No") -> No
A13: =ROW()-1 -> 12 | B13: 250015 | C13: On-Board | D13: Abdelrahman Esam | E13: عبدالرحمن عصام لطفي | F13: مهندس تكنولوجيا معلومات | G13: IT Engineer | I13: =IFERROR(VLOOKUP(H13,'SI Codes'!$A:$B,2,FALSE()),"") | J13: Engineering | K13: =IFERROR(VLOOKUP(J13,Lists!$I$1:$J$21,2,FALSE()),"") -> Operations | L13: Factory 1 | M13: Saturdays and Fridays | N13: No | O13: No | Q13: 45775 | R13: =IF(Q13="","",IF(C13="Resigned",IF(AX13="","",DATEDIF(Q13,AX13,"y")&"y "&DATEDIF(Q13,AX13,"ym")&"m"),DATEDIF(Q13,TODAY(),"y")&"y "&DATEDIF(Q13,TODAY(),"ym")&"m")) -> 0y 8m | S13: 1119470848 | T13: 1272841451 | U13: 87066305 | V13: Yes | Z13: 30512031302698 | AA13: =IFERROR(DATE(IF(LEFT(Z13,1)="2",1900,2000)+VALUE(MID(Z13,2,2)),VALUE(MID(Z13,4,2)),VALUE(MID(Z13,6,2))),"") -> 38689 | AB13: =IF(AA13="","",DATEDIF(AA13,TODAY(),"y")&"y "&DATEDIF(AA13,TODAY(),"ym")&"m") -> 20y 0m | AE13: Male | AG13: Single | AH13: Muslim | AI13: ثانوية عامة | AU13: =IF(COUNTIF(AJ13:AT13,"Yes")=COLUMNS(AJ13:AT13),"Yes","No") -> No
A14: =ROW()-1 -> 13 | B14: 250016 | C14: On-Board | D14: Ahmed Youssef | E14: احمد يوسف عبدالعظيم | F14: فني انتاج | G14: Production Operator | I14: =IFERROR(VLOOKUP(H14,'SI Codes'!$A:$B,2,FALSE()),"") | J14: Production | K14: =IFERROR(VLOOKUP(J14,Lists!$I$1:$J$21,2,FALSE()),"") -> Operations | L14: Factory 1 | M14: Fridays Only | N14: Yes | O14: Yes | Q14: 45795 | R14: =IF(Q14="","",IF(C14="Resigned",IF(AX14="","",DATEDIF(Q14,AX14,"y")&"y "&DATEDIF(Q14,AX14,"ym")&"m"),DATEDIF(Q14,TODAY(),"y")&"y "&DATEDIF(Q14,TODAY(),"ym")&"m")) -> 0y 7m | S14: 1116410302 | T14: 1127682219 | U14: 68792755 | V14: Yes | Z14: 29105302100298 | AA14: =IFERROR(DATE(IF(LEFT(Z14,1)="2",1900,2000)+VALUE(MID(Z14,2,2)),VALUE(MID(Z14,4,2)),VALUE(MID(Z14,6,2))),"") -> 33388 | AB14: =IF(AA14="","",DATEDIF(AA14,TODAY(),"y")&"y "&DATEDIF(AA14,TODAY(),"ym")&"m") -> 34y 7m | AE14: Male | AG14: Married | AH14: Muslim | AI14: دبلوم زراعة | AU14: =IF(COUNTIF(AJ14:AT14,"Yes")=COLUMNS(AJ14:AT14),"Yes","No") -> No
A15: =ROW()-1 -> 14 | B15: 250017 | C15: On-Board | D15: Ahmed Bheg | E15: احمد بهيج رشدي | F15: عامل خدمات | G15: Clean Service | I15: =IFERROR(VLOOKUP(H15,'SI Codes'!$A:$B,2,FALSE()),"") | J15: Service | K15: =IFERROR(VLOOKUP(J15,Lists!$I$1:$J$21,2,FALSE()),"") -> HR and Admin | L15: Factory 1 | M15: Fridays Only | N15: Yes | O15: Yes | Q15: 45788 | R15: =IF(Q15="","",IF(C15="Resigned",IF(AX15="","",DATEDIF(Q15,AX15,"y")&"y "&DATEDIF(Q15,AX15,"ym")&"m"),DATEDIF(Q15,TODAY(),"y")&"y "&DATEDIF(Q15,TODAY(),"ym")&"m")) -> 0y 7m | S15: 1123898859 | U15: 43630698 | V15: Yes | Z15: 29011080103957 | AA15: =IFERROR(DATE(IF(LEFT(Z15,1)="2",1900,2000)+VALUE(MID(Z15,2,2)),VALUE(MID(Z15,4,2)),VALUE(MID(Z15,6,2))),"") -> 33185 | AB15: =IF(AA15="","",DATEDIF(AA15,TODAY(),"y")&"y "&DATEDIF(AA15,TODAY(),"ym")&"m") -> 35y 1m | AE15: Male | AG15: Single | AH15: Muslim | AI15: بدون مؤهل | AU15: =IF(COUNTIF(AJ15:AT15,"Yes")=COLUMNS(AJ15:AT15),"Yes","No") -> No
A16: =ROW()-1 -> 15 | B16: 250018 | C16: On-Board | D16: Abdelrahman Abdo | E16: عبدالرحمن عبده رمضان | F16: مندوب | G16: Representative | I16: =IFERROR(VLOOKUP(H16,'SI Codes'!$A:$B,2,FALSE()),"") | J16: Local Purchasing | K16: =IFERROR(VLOOKUP(J16,Lists!$I$1:$J$21,2,FALSE()),"") -> Supply Chain | L16: Factory 1 | M16: Saturdays and Fridays | N16: No | O16: No | Q16: 45796 | R16: =IF(Q16="","",IF(C16="Resigned",IF(AX16="","",DATEDIF(Q16,AX16,"y")&"y "&DATEDIF(Q16,AX16,"ym")&"m"),DATEDIF(Q16,TODAY(),"y")&"y "&DATEDIF(Q16,TODAY(),"ym")&"m")) -> 0y 7m | S16: 1121235909 | U16: 86813304 | V16: Yes | Z16: 29806032800738 | AA16: =IFERROR(DATE(IF(LEFT(Z16,1)="2",1900,2000)+VALUE(MID(Z16,2,2)),VALUE(MID(Z16,4,2)),VALUE(MID(Z16,6,2))),"") -> 35949 | AB16: =IF(AA16="","",DATEDIF(AA16,TODAY(),"y")&"y "&DATEDIF(AA16,TODAY(),"ym")&"m") -> 27y 6m | AE16: Male | AG16: Single | AH16: Muslim | AU16: =IF(COUNTIF(AJ16:AT16,"Yes")=COLUMNS(AJ16:AT16),"Yes","No") -> No
A17: =ROW()-1 -> 16 | I17: =IFERROR(VLOOKUP(H17,'SI Codes'!$A:$B,2,FALSE()),"") | K17: =IFERROR(VLOOKUP(J17,Lists!$I$1:$J$21,2,FALSE()),"") | R17: =IF(Q17="","",IF(C17="Resigned",IF(AX17="","",DATEDIF(Q17,AX17,"y")&"y "&DATEDIF(Q17,AX17,"ym")&"m"),DATEDIF(Q17,TODAY(),"y")&"y "&DATEDIF(Q17,TODAY(),"ym")&"m")) | AA17: =IFERROR(DATE(IF(LEFT(Z17,1)="2",1900,2000)+VALUE(MID(Z17,2,2)),VALUE(MID(Z17,4,2)),VALUE(MID(Z17,6,2))),"") | AB17: =IF(AA17="","",DATEDIF(AA17,TODAY(),"y")&"y "&DATEDIF(AA17,TODAY(),"ym")&"m") | AU17: =IF(COUNTIF(AJ17:AT17,"Yes")=COLUMNS(AJ17:AT17),"Yes","No") -> No
A18: =ROW()-1 -> 17 | I18: =IFERROR(VLOOKUP(H18,'SI Codes'!$A:$B,2,FALSE()),"") | K18: =IFERROR(VLOOKUP(J18,Lists!$I$1:$J$21,2,FALSE()),"") | R18: =IF(Q18="","",IF(C18="Resigned",IF(AX18="","",DATEDIF(Q18,AX18,"y")&"y "&DATEDIF(Q18,AX18,"ym")&"m"),DATEDIF(Q18,TODAY(),"y")&"y "&DATEDIF(Q18,TODAY(),"ym")&"m")) | AA18: =IFERROR(DATE(IF(LEFT(Z18,1)="2",1900,2000)+VALUE(MID(Z18,2,2)),VALUE(MID(Z18,4,2)),VALUE(MID(Z18,6,2))),"") | AB18: =IF(AA18="","",DATEDIF(AA18,TODAY(),"y")&"y "&DATEDIF(AA18,TODAY(),"ym")&"m") | AU18: =IF(COUNTIF(AJ18:AT18,"Yes")=COLUMNS(AJ18:AT18),"Yes","No") -> No
A19: =ROW()-1 -> 18 | I19: =IFERROR(VLOOKUP(H19,'SI Codes'!$A:$B,2,FALSE()),"") | K19: =IFERROR(VLOOKUP(J19,Lists!$I$1:$J$21,2,FALSE()),"") | R19: =IF(Q19="","",IF(C19="Resigned",IF(AX19="","",DATEDIF(Q19,AX19,"y")&"y "&DATEDIF(Q19,AX19,"ym")&"m"),DATEDIF(Q19,TODAY(),"y")&"y "&DATEDIF(Q19,TODAY(),"ym")&"m")) | AA19: =IFERROR(DATE(IF(LEFT(Z19,1)="2",1900,2000)+VALUE(MID(Z19,2,2)),VALUE(MID(Z19,4,2)),VALUE(MID(Z19,6,2))),"") | AB19: =IF(AA19="","",DATEDIF(AA19,TODAY(),"y")&"y "&DATEDIF(AA19,TODAY(),"ym")&"m") | AU19: =IF(COUNTIF(AJ19:AT19,"Yes")=COLUMNS(AJ19:AT19),"Yes","No") -> No
A20: =ROW()-1 -> 19 | I20: =IFERROR(VLOOKUP(H20,'SI Codes'!$A:$B,2,FALSE()),"") | K20: =IFERROR(VLOOKUP(J20,Lists!$I$1:$J$21,2,FALSE()),"") | R20: =IF(Q20="","",IF(C20="Resigned",IF(AX20="","",DATEDIF(Q20,AX20,"y")&"y "&DATEDIF(Q20,AX20,"ym")&"m"),DATEDIF(Q20,TODAY(),"y")&"y "&DATEDIF(Q20,TODAY(),"ym")&"m")) | AA20: =IFERROR(DATE(IF(LEFT(Z20,1)="2",1900,2000)+VALUE(MID(Z20,2,2)),VALUE(MID(Z20,4,2)),VALUE(MID(Z20,6,2))),"") | AB20: =IF(AA20="","",DATEDIF(AA20,TODAY(),"y")&"y "&DATEDIF(AA20,TODAY(),"ym")&"m") | AU20: =IF(COUNTIF(AJ20:AT20,"Yes")=COLUMNS(AJ20:AT20),"Yes","No") -> No
A21: =ROW()-1 -> 20 | I21: =IFERROR(VLOOKUP(H21,'SI Codes'!$A:$B,2,FALSE()),"") | K21: =IFERROR(VLOOKUP(J21,Lists!$I$1:$J$21,2,FALSE()),"") | R21: =IF(Q21="","",IF(C21="Resigned",IF(AX21="","",DATEDIF(Q21,AX21,"y")&"y "&DATEDIF(Q21,AX21,"ym")&"m"),DATEDIF(Q21,TODAY(),"y")&"y "&DATEDIF(Q21,TODAY(),"ym")&"m")) | AA21: =IFERROR(DATE(IF(LEFT(Z21,1)="2",1900,2000)+VALUE(MID(Z21,2,2)),VALUE(MID(Z21,4,2)),VALUE(MID(Z21,6,2))),"") | AB21: =IF(AA21="","",DATEDIF(AA21,TODAY(),"y")&"y "&DATEDIF(AA21,TODAY(),"ym")&"m") | AU21: =IF(COUNTIF(AJ21:AT21,"Yes")=COLUMNS(AJ21:AT21),"Yes","No") -> No
A22: =ROW()-1 -> 21 | I22: =IFERROR(VLOOKUP(H22,'SI Codes'!$A:$B,2,FALSE()),"") | K22: =IFERROR(VLOOKUP(J22,Lists!$I$1:$J$21,2,FALSE()),"") | R22: =IF(Q22="","",IF(C22="Resigned",IF(AX22="","",DATEDIF(Q22,AX22,"y")&"y "&DATEDIF(Q22,AX22,"ym")&"m"),DATEDIF(Q22,TODAY(),"y")&"y "&DATEDIF(Q22,TODAY(),"ym")&"m")) | AA22: =IFERROR(DATE(IF(LEFT(Z22,1)="2",1900,2000)+VALUE(MID(Z22,2,2)),VALUE(MID(Z22,4,2)),VALUE(MID(Z22,6,2))),"") | AB22: =IF(AA22="","",DATEDIF(AA22,TODAY(),"y")&"y "&DATEDIF(AA22,TODAY(),"ym")&"m") | AU22: =IF(COUNTIF(AJ22:AT22,"Yes")=COLUMNS(AJ22:AT22),"Yes","No") -> No
A23: =ROW()-1 -> 22 | I23: =IFERROR(VLOOKUP(H23,'SI Codes'!$A:$B,2,FALSE()),"") | K23: =IFERROR(VLOOKUP(J23,Lists!$I$1:$J$21,2,FALSE()),"") | R23: =IF(Q23="","",IF(C23="Resigned",IF(AX23="","",DATEDIF(Q23,AX23,"y")&"y "&DATEDIF(Q23,AX23,"ym")&"m"),DATEDIF(Q23,TODAY(),"y")&"y "&DATEDIF(Q23,TODAY(),"ym")&"m")) | AA23: =IFERROR(DATE(IF(LEFT(Z23,1)="2",1900,2000)+VALUE(MID(Z23,2,2)),VALUE(MID(Z23,4,2)),VALUE(MID(Z23,6,2))),"") | AB23: =IF(AA23="","",DATEDIF(AA23,TODAY(),"y")&"y "&DATEDIF(AA23,TODAY(),"ym")&"m") | AU23: =IF(COUNTIF(AJ23:AT23,"Yes")=COLUMNS(AJ23:AT23),"Yes","No") -> No
A24: =ROW()-1 -> 23 | I24: =IFERROR(VLOOKUP(H24,'SI Codes'!$A:$B,2,FALSE()),"") | K24: =IFERROR(VLOOKUP(J24,Lists!$I$1:$J$21,2,FALSE()),"") | R24: =IF(Q24="","",IF(C24="Resigned",IF(AX24="","",DATEDIF(Q24,AX24,"y")&"y "&DATEDIF(Q24,AX24,"ym")&"m"),DATEDIF(Q24,TODAY(),"y")&"y "&DATEDIF(Q24,TODAY(),"ym")&"m")) | AA24: =IFERROR(DATE(IF(LEFT(Z24,1)="2",1900,2000)+VALUE(MID(Z24,2,2)),VALUE(MID(Z24,4,2)),VALUE(MID(Z24,6,2))),"") | AB24: =IF(AA24="","",DATEDIF(AA24,TODAY(),"y")&"y "&DATEDIF(AA24,TODAY(),"ym")&"m") | AU24: =IF(COUNTIF(AJ24:AT24,"Yes")=COLUMNS(AJ24:AT24),"Yes","No") -> No
A25: =ROW()-1 -> 24 | I25: =IFERROR(VLOOKUP(H25,'SI Codes'!$A:$B,2,FALSE()),"") | K25: =IFERROR(VLOOKUP(J25,Lists!$I$1:$J$21,2,FALSE()),"") | R25: =IF(Q25="","",IF(C25="Resigned",IF(AX25="","",DATEDIF(Q25,AX25,"y")&"y "&DATEDIF(Q25,AX25,"ym")&"m"),DATEDIF(Q25,TODAY(),"y")&"y "&DATEDIF(Q25,TODAY(),"ym")&"m")) | AA25: =IFERROR(DATE(IF(LEFT(Z25,1)="2",1900,2000)+VALUE(MID(Z25,2,2)),VALUE(MID(Z25,4,2)),VALUE(MID(Z25,6,2))),"") | AB25: =IF(AA25="","",DATEDIF(AA25,TODAY(),"y")&"y "&DATEDIF(AA25,TODAY(),"ym")&"m") | AU25: =IF(COUNTIF(AJ25:AT25,"Yes")=COLUMNS(AJ25:AT25),"Yes","No") -> No
A26: =ROW()-1 -> 25 | I26: =IFERROR(VLOOKUP(H26,'SI Codes'!$A:$B,2,FALSE()),"") | K26: =IFERROR(VLOOKUP(J26,Lists!$I$1:$J$21,2,FALSE()),"") | R26: =IF(Q26="","",IF(C26="Resigned",IF(AX26="","",DATEDIF(Q26,AX26,"y")&"y "&DATEDIF(Q26,AX26,"ym")&"m"),DATEDIF(Q26,TODAY(),"y")&"y "&DATEDIF(Q26,TODAY(),"ym")&"m")) | AA26: =IFERROR(DATE(IF(LEFT(Z26,1)="2",1900,2000)+VALUE(MID(Z26,2,2)),VALUE(MID(Z26,4,2)),VALUE(MID(Z26,6,2))),"") | AB26: =IF(AA26="","",DATEDIF(AA26,TODAY(),"y")&"y "&DATEDIF(AA26,TODAY(),"ym")&"m") | AU26: =IF(COUNTIF(AJ26:AT26,"Yes")=COLUMNS(AJ26:AT26),"Yes","No") -> No
A27: =ROW()-1 -> 26 | I27: =IFERROR(VLOOKUP(H27,'SI Codes'!$A:$B,2,FALSE()),"") | K27: =IFERROR(VLOOKUP(J27,Lists!$I$1:$J$21,2,FALSE()),"") | R27: =IF(Q27="","",IF(C27="Resigned",IF(AX27="","",DATEDIF(Q27,AX27,"y")&"y "&DATEDIF(Q27,AX27,"ym")&"m"),DATEDIF(Q27,TODAY(),"y")&"y "&DATEDIF(Q27,TODAY(),"ym")&"m")) | AA27: =IFERROR(DATE(IF(LEFT(Z27,1)="2",1900,2000)+VALUE(MID(Z27,2,2)),VALUE(MID(Z27,4,2)),VALUE(MID(Z27,6,2))),"") | AB27: =IF(AA27="","",DATEDIF(AA27,TODAY(),"y")&"y "&DATEDIF(AA27,TODAY(),"ym")&"m") | AU27: =IF(COUNTIF(AJ27:AT27,"Yes")=COLUMNS(AJ27:AT27),"Yes","No") -> No
A28: =ROW()-1 -> 27 | I28: =IFERROR(VLOOKUP(H28,'SI Codes'!$A:$B,2,FALSE()),"") | K28: =IFERROR(VLOOKUP(J28,Lists!$I$1:$J$21,2,FALSE()),"") | R28: =IF(Q28="","",IF(C28="Resigned",IF(AX28="","",DATEDIF(Q28,AX28,"y")&"y "&DATEDIF(Q28,AX28,"ym")&"m"),DATEDIF(Q28,TODAY(),"y")&"y "&DATEDIF(Q28,TODAY(),"ym")&"m")) | AA28: =IFERROR(DATE(IF(LEFT(Z28,1)="2",1900,2000)+VALUE(MID(Z28,2,2)),VALUE(MID(Z28,4,2)),VALUE(MID(Z28,6,2))),"") | AB28: =IF(AA28="","",DATEDIF(AA28,TODAY(),"y")&"y "&DATEDIF(AA28,TODAY(),"ym")&"m") | AU28: =IF(COUNTIF(AJ28:AT28,"Yes")=COLUMNS(AJ28:AT28),"Yes","No") -> No
... A51: =ROW()-1 -> 50 | I51: =IFERROR(VLOOKUP(H51,'SI Codes'!$A:$B,2,FALSE()),"") | K51: =IFERROR(VLOOKUP(J51,Lists!$I$1:$J$21,2,FALSE()),"") | R51: =IF(Q51="","",IF(C51="Resigned",IF(AX51="","",DATEDIF(Q51,AX51,"y")&"y "&DATEDIF(Q51,AX51,"ym")&"m"),DATEDIF(Q51,TODAY(),"y")&"y "&DATEDIF(Q51,TODAY(),"ym")&"m")) | AA51: =IFERROR(DATE(IF(LEFT(Z51,1)="2",1900,2000)+VALUE(MID(Z51,2,2)),VALUE(MID(Z51,4,2)),VALUE(MID(Z51,6,2))),"") | AB51: =IF(AA51="","",DATEDIF(AA51,TODAY(),"y")&"y "&DATEDIF(AA51,TODAY(),"ym")&"m") | AU51: =IF(COUNTIF(AJ51:AT51,"Yes")=COLUMNS(AJ51:AT51),"Yes","No") -> No
A52: =ROW()-1 -> 51 | K52: =IFERROR(VLOOKUP(J52,Lists!$I$1:$J$21,2,FALSE()),"") | AU52: =IF(COUNTIF(AJ52:AT52,"Yes")=COLUMNS(AJ52:AT52),"Yes","No") -> No
A53: =ROW()-1 -> 52 | K53: =IFERROR(VLOOKUP(J53,Lists!$I$1:$J$21,2,FALSE()),"") | AU53: =IF(COUNTIF(AJ53:AT53,"Yes")=COLUMNS(AJ53:AT53),"Yes","No") -> No
A54: =ROW()-1 -> 53 | K54: =IFERROR(VLOOKUP(J54,Lists!$I$1:$J$21,2,FALSE()),"") | AU54: =IF(COUNTIF(AJ54:AT54,"Yes")=COLUMNS(AJ54:AT54),"Yes","No") -> No
A55: =ROW()-1 -> 54 | K55: =IFERROR(VLOOKUP(J55,Lists!$I$1:$J$21,2,FALSE()),"") | AU55: =IF(COUNTIF(AJ55:AT55,"Yes")=COLUMNS(AJ55:AT55),"Yes","No") -> No
A56: =ROW()-1 -> 55 | K56: =IFERROR(VLOOKUP(J56,Lists!$I$1:$J$21,2,FALSE()),"") | AU56: =IF(COUNTIF(AJ56:AT56,"Yes")=COLUMNS(AJ56:AT56),"Yes","No") -> No
A57: =ROW()-1 -> 56 | K57: =IFERROR(VLOOKUP(J57,Lists!$I$1:$J$21,2,FALSE()),"") | AU57: =IF(COUNTIF(AJ57:AT57,"Yes")=COLUMNS(AJ57:AT57),"Yes","No") -> No
A58: =ROW()-1 -> 57 | K58: =IFERROR(VLOOKUP(J58,Lists!$I$1:$J$21,2,FALSE()),"") | AU58: =IF(COUNTIF(AJ58:AT58,"Yes")=COLUMNS(AJ58:AT58),"Yes","No") -> No
A59: =ROW()-1 -> 58 | K59: =IFERROR(VLOOKUP(J59,Lists!$I$1:$J$21,2,FALSE()),"") | AU59: =IF(COUNTIF(AJ59:AT59,"Yes")=COLUMNS(AJ59:AT59),"Yes","No") -> No
A60: =ROW()-1 -> 59 | K60: =IFERROR(VLOOKUP(J60,Lists!$I$1:$J$21,2,FALSE()),"") | AU60: =IF(COUNTIF(AJ60:AT60,"Yes")=COLUMNS(AJ60:AT60),"Yes","No") -> No
A61: =ROW()-1 -> 60 | K61: =IFERROR(VLOOKUP(J61,Lists!$I$1:$J$21,2,FALSE()),"") | AU61: =IF(COUNTIF(AJ61:AT61,"Yes")=COLUMNS(AJ61:AT61),"Yes","No") -> No
A62: =ROW()-1 -> 61 | K62: =IFERROR(VLOOKUP(J62,Lists!$I$1:$J$21,2,FALSE()),"") | AU62: =IF(COUNTIF(AJ62:AT62,"Yes")=COLUMNS(AJ62:AT62),"Yes","No") -> No
...

Sheet Lists
A1: WorkingStatus | B1: Site | C1: WeeklyDaysOff | D1: BusRoute | E1: MilitaryService | F1: SI Basic Wage | G1: SI Gross Wage | I1: Department | J1: Sector
A2: On-Board | B2: Admin | C2: Fridays Only | D2: October | E2: Postponed | F2: 5500 | G2: 5500 | I2: CEO | J2: GM
A3: Notice Period | B3: Factory 1 | C3: Saturdays and Fridays | D3: Giza | E3: Exempted | F3: 16700 | G3: =Table4[[#This Row],[SI Basic Wage]]*1.3 -> 21710 | I3: Production | J3: Operations
A4: Resigned | B4: Factory 2 | D4: Cairo | E4: Served | I4: Quality | J4: Operations
A5: Absent | I5: Maintenance | J5: Operations
A6: Court Case | I6: Engineering | J6: Operations
A7: Dead | I7: Tendering | J7: R&D
I8: Validation | J8: R&D
I9: Finance | J9: Finance
I10: Collection | J10: Finance
I11: Warehouse | J11: Finance
I12: Foreign Purchasing | J12: Supply Chain
I13: Local Purchasing | J13: Supply Chain
I14: Sales | J14: Supply Chain
I15: Legal Affairs | J15: HR and Admin
I16: HR | J16: HR and Admin
I17: Buffet | J17: HR and Admin
I18: Service | J18: HR and Admin
I19: Security | J19: HR and Admin
... I21: Public Affairs | J21: HR and Admin

Sheet SI Codes
A1: Job Code | B1: Title
A2: 11000 | B2: دكتور كيميائى
A3: 11100 | B3: كيميائي عام
A4: 11200 | B4: كيميائي متخصص في الكيمياء العضويه
A5: 11300 | B5: كيميائي متخصص في كمياء غير عضويه
A6: 11400 | B6: كميائي متخصص في كمياء طبيعيه
A7: 11500 | B7: كميائي متخصص في التحاليل
A8: 11900 | B8: الكميائيون الخرون
A9: 12000 | B9: جيوفيزيقى
A10: 12100 | B10: فيزيائي عام
A11: 12200 | B11: فيزيائي متخصص في الميكانيكا
A12: 12300 | B12: فيزيائي متخصص في الحراره
A13: 12400 | B13: فيزيائي متخصص في الضوء
... A3053: 999999 | B3053: صاحب معاش
